/oscar/data/deeps/private/bfoxkemp/jnickla1/Thorne_15_codefigurestats/fut_evaluation_gen_ensemble.py:21: RuntimeWarning: Mean of empty slice
  return np.nanmean(standards_np,axis=0)
/oscar/data/deeps/private/bfoxkemp/jnickla1/Thorne_15_codefigurestats/fut_evaluation_gen_ensemble.py:21: RuntimeWarning: Mean of empty slice
  return np.nanmean(standards_np,axis=0)
/oscar/data/deeps/private/bfoxkemp/jnickla1/Thorne_15_codefigurestats/fut_evaluation_gen_ensemble.py:21: RuntimeWarning: Mean of empty slice
  return np.nanmean(standards_np,axis=0)
/oscar/data/deeps/private/bfoxkemp/jnickla1/Thorne_15_codefigurestats/fut_evaluation_gen_ensemble.py:21: RuntimeWarning: Mean of empty slice
  return np.nanmean(standards_np,axis=0)
/oscar/data/deeps/private/bfoxkemp/jnickla1/Thorne_15_codefigurestats/fut_evaluation_gen_ensemble.py:21: RuntimeWarning: Mean of empty slice
  return np.nanmean(standards_np,axis=0)
starting computation for fut_NorESM_RCP45_VolcConst
max_runs48
Model number:
46




Methods/42_Temp_Alone/1_Run_Means/cent20y_method.py
starting computation for fut_NorESM_RCP45_Volc
max_runs48
Model number:
46




Methods/42_Temp_Alone/1_Run_Means/cent20y_method.py
Traceback (most recent call last):
  File "/users/jnickla1/.conda/envs/cleanpy/lib/python3.13/site-packages/pandas/core/indexes/range.py", line 413, in get_loc
    return self._range.index(new_key)
           ~~~~~~~~~~~~~~~~~^^^^^^^^^
ValueError: 157 is not in range

The above exception was the direct cause of the following exception:

Traceback (most recent call last):
Traceback (most recent call last):
  File "/users/jnickla1/.conda/envs/cleanpy/lib/python3.13/site-packages/pandas/core/indexes/range.py", line 413, in get_loc
    return self._range.index(new_key)
           ~~~~~~~~~~~~~~~~~^^^^^^^^^
ValueError: 157 is not in range

The above exception was the direct cause of the following exception:

Traceback (most recent call last):
  File "/oscar/data/deeps/private/bfoxkemp/jnickla1/Thorne_15_codefigurestats/fut_evaluation_script.py", line 638, in <module>
    run_one_single_ens_member(plotting_figs, experiment_type, start_run, None, None)
    ~~~~~~~~~~~~~~~~~~~~~~~~~^^^^^^^^^^^^^^^^^^^^^^^^^^^^^^^^^^^^^^^^^^^^^^^^^^^^^^^
  File "/oscar/data/deeps/private/bfoxkemp/jnickla1/Thorne_15_codefigurestats/fut_evaluation_script.py", line 163, in run_one_single_ens_member
    results = run_methods(years, simall,
                          (np.concatenate((temps_CIl_hist,futCIl)), np.concatenate((temps_CIu_hist,futCIu)) ),
                          model_run, experiment_type, methods_folder)
  File "/oscar/data/deeps/private/bfoxkemp/jnickla1/Thorne_15_codefigurestats/hist_evaluation_script.py", line 108, in run_methods
    result = method_module.run_method(years, avg_temperatures, temp_uncert,model_run, experiment_type)
  File "/oscar/data/deeps/private/bfoxkemp/jnickla1/Thorne_15_codefigurestats/Methods/42_Temp_Alone/1_Run_Means/cent20y_method.py", line 23, in run_method
    tot_uncertb = (hadcrutUncert[i-avg_len_l+1])**2
                   ~~~~~~~~~~~~~^^^^^^^^^^^^^^^
  File "/users/jnickla1/.conda/envs/cleanpy/lib/python3.13/site-packages/pandas/core/series.py", line 1121, in __getitem__
    return self._get_value(key)
           ~~~~~~~~~~~~~~~^^^^^
  File "/users/jnickla1/.conda/envs/cleanpy/lib/python3.13/site-packages/pandas/core/series.py", line 1237, in _get_value
    loc = self.index.get_loc(label)
  File "/users/jnickla1/.conda/envs/cleanpy/lib/python3.13/site-packages/pandas/core/indexes/range.py", line 415, in get_loc
    raise KeyError(key) from err
KeyError: 157
  File "/oscar/data/deeps/private/bfoxkemp/jnickla1/Thorne_15_codefigurestats/fut_evaluation_script.py", line 638, in <module>
    run_one_single_ens_member(plotting_figs, experiment_type, start_run, None, None)
    ~~~~~~~~~~~~~~~~~~~~~~~~~^^^^^^^^^^^^^^^^^^^^^^^^^^^^^^^^^^^^^^^^^^^^^^^^^^^^^^^
  File "/oscar/data/deeps/private/bfoxkemp/jnickla1/Thorne_15_codefigurestats/fut_evaluation_script.py", line 163, in run_one_single_ens_member
    results = run_methods(years, simall,
                          (np.concatenate((temps_CIl_hist,futCIl)), np.concatenate((temps_CIu_hist,futCIu)) ),
                          model_run, experiment_type, methods_folder)
  File "/oscar/data/deeps/private/bfoxkemp/jnickla1/Thorne_15_codefigurestats/hist_evaluation_script.py", line 108, in run_methods
    result = method_module.run_method(years, avg_temperatures, temp_uncert,model_run, experiment_type)
  File "/oscar/data/deeps/private/bfoxkemp/jnickla1/Thorne_15_codefigurestats/Methods/42_Temp_Alone/1_Run_Means/cent20y_method.py", line 23, in run_method
    tot_uncertb = (hadcrutUncert[i-avg_len_l+1])**2
                   ~~~~~~~~~~~~~^^^^^^^^^^^^^^^
  File "/users/jnickla1/.conda/envs/cleanpy/lib/python3.13/site-packages/pandas/core/series.py", line 1121, in __getitem__
    return self._get_value(key)
           ~~~~~~~~~~~~~~~^^^^^
  File "/users/jnickla1/.conda/envs/cleanpy/lib/python3.13/site-packages/pandas/core/series.py", line 1237, in _get_value
    loc = self.index.get_loc(label)
  File "/users/jnickla1/.conda/envs/cleanpy/lib/python3.13/site-packages/pandas/core/indexes/range.py", line 415, in get_loc
    raise KeyError(key) from err
KeyError: 157
starting computation for fut_ESM1-2-LR_SSP370_constVolc
max_runs48
Model number:
46




Methods/42_Temp_Alone/1_Run_Means/cent20y_method.py
starting computation for fut_ESM1-2-LR_SSP126_constVolc
max_runs48
Model number:
46




Methods/42_Temp_Alone/1_Run_Means/cent20y_method.py
Traceback (most recent call last):
  File "/users/jnickla1/.conda/envs/cleanpy/lib/python3.13/site-packages/pandas/core/indexes/range.py", line 413, in get_loc
    return self._range.index(new_key)
           ~~~~~~~~~~~~~~~~~^^^^^^^^^
ValueError: 157 is not in range

The above exception was the direct cause of the following exception:

Traceback (most recent call last):
  File "/oscar/data/deeps/private/bfoxkemp/jnickla1/Thorne_15_codefigurestats/fut_evaluation_script.py", line 638, in <module>
    run_one_single_ens_member(plotting_figs, experiment_type, start_run, None, None)
    ~~~~~~~~~~~~~~~~~~~~~~~~~^^^^^^^^^^^^^^^^^^^^^^^^^^^^^^^^^^^^^^^^^^^^^^^^^^^^^^^
  File "/oscar/data/deeps/private/bfoxkemp/jnickla1/Thorne_15_codefigurestats/fut_evaluation_script.py", line 163, in run_one_single_ens_member
    results = run_methods(years, simall,
                          (np.concatenate((temps_CIl_hist,futCIl)), np.concatenate((temps_CIu_hist,futCIu)) ),
                          model_run, experiment_type, methods_folder)
  File "/oscar/data/deeps/private/bfoxkemp/jnickla1/Thorne_15_codefigurestats/hist_evaluation_script.py", line 108, in run_methods
    result = method_module.run_method(years, avg_temperatures, temp_uncert,model_run, experiment_type)
  File "/oscar/data/deeps/private/bfoxkemp/jnickla1/Thorne_15_codefigurestats/Methods/42_Temp_Alone/1_Run_Means/cent20y_method.py", line 23, in run_method
    tot_uncertb = (hadcrutUncert[i-avg_len_l+1])**2
                   ~~~~~~~~~~~~~^^^^^^^^^^^^^^^
  File "/users/jnickla1/.conda/envs/cleanpy/lib/python3.13/site-packages/pandas/core/series.py", line 1121, in __getitem__
    return self._get_value(key)
           ~~~~~~~~~~~~~~~^^^^^
  File "/users/jnickla1/.conda/envs/cleanpy/lib/python3.13/site-packages/pandas/core/series.py", line 1237, in _get_value
    loc = self.index.get_loc(label)
  File "/users/jnickla1/.conda/envs/cleanpy/lib/python3.13/site-packages/pandas/core/indexes/range.py", line 415, in get_loc
    raise KeyError(key) from err
KeyError: 157
starting computation for fut_ESM1-2-LR_SSP245_constVolc
max_runs48
Model number:
46




Methods/42_Temp_Alone/1_Run_Means/cent20y_method.py
Traceback (most recent call last):
  File "/users/jnickla1/.conda/envs/cleanpy/lib/python3.13/site-packages/pandas/core/indexes/range.py", line 413, in get_loc
    return self._range.index(new_key)
           ~~~~~~~~~~~~~~~~~^^^^^^^^^
ValueError: 157 is not in range

The above exception was the direct cause of the following exception:

Traceback (most recent call last):
  File "/oscar/data/deeps/private/bfoxkemp/jnickla1/Thorne_15_codefigurestats/fut_evaluation_script.py", line 638, in <module>
    run_one_single_ens_member(plotting_figs, experiment_type, start_run, None, None)
    ~~~~~~~~~~~~~~~~~~~~~~~~~^^^^^^^^^^^^^^^^^^^^^^^^^^^^^^^^^^^^^^^^^^^^^^^^^^^^^^^
  File "/oscar/data/deeps/private/bfoxkemp/jnickla1/Thorne_15_codefigurestats/fut_evaluation_script.py", line 163, in run_one_single_ens_member
    results = run_methods(years, simall,
                          (np.concatenate((temps_CIl_hist,futCIl)), np.concatenate((temps_CIu_hist,futCIu)) ),
                          model_run, experiment_type, methods_folder)
  File "/oscar/data/deeps/private/bfoxkemp/jnickla1/Thorne_15_codefigurestats/hist_evaluation_script.py", line 108, in run_methods
    result = method_module.run_method(years, avg_temperatures, temp_uncert,model_run, experiment_type)
  File "/oscar/data/deeps/private/bfoxkemp/jnickla1/Thorne_15_codefigurestats/Methods/42_Temp_Alone/1_Run_Means/cent20y_method.py", line 23, in run_method
    tot_uncertb = (hadcrutUncert[i-avg_len_l+1])**2
                   ~~~~~~~~~~~~~^^^^^^^^^^^^^^^
  File "/users/jnickla1/.conda/envs/cleanpy/lib/python3.13/site-packages/pandas/core/series.py", line 1121, in __getitem__
    return self._get_value(key)
           ~~~~~~~~~~~~~~~^^^^^
  File "/users/jnickla1/.conda/envs/cleanpy/lib/python3.13/site-packages/pandas/core/series.py", line 1237, in _get_value
    loc = self.index.get_loc(label)
  File "/users/jnickla1/.conda/envs/cleanpy/lib/python3.13/site-packages/pandas/core/indexes/range.py", line 415, in get_loc
    raise KeyError(key) from err
KeyError: 157
Traceback (most recent call last):
  File "/users/jnickla1/.conda/envs/cleanpy/lib/python3.13/site-packages/pandas/core/indexes/range.py", line 413, in get_loc
    return self._range.index(new_key)
           ~~~~~~~~~~~~~~~~~^^^^^^^^^
ValueError: 157 is not in range

The above exception was the direct cause of the following exception:

Traceback (most recent call last):
  File "/oscar/data/deeps/private/bfoxkemp/jnickla1/Thorne_15_codefigurestats/fut_evaluation_script.py", line 638, in <module>
    run_one_single_ens_member(plotting_figs, experiment_type, start_run, None, None)
    ~~~~~~~~~~~~~~~~~~~~~~~~~^^^^^^^^^^^^^^^^^^^^^^^^^^^^^^^^^^^^^^^^^^^^^^^^^^^^^^^
  File "/oscar/data/deeps/private/bfoxkemp/jnickla1/Thorne_15_codefigurestats/fut_evaluation_script.py", line 163, in run_one_single_ens_member
    results = run_methods(years, simall,
                          (np.concatenate((temps_CIl_hist,futCIl)), np.concatenate((temps_CIu_hist,futCIu)) ),
                          model_run, experiment_type, methods_folder)
  File "/oscar/data/deeps/private/bfoxkemp/jnickla1/Thorne_15_codefigurestats/hist_evaluation_script.py", line 108, in run_methods
    result = method_module.run_method(years, avg_temperatures, temp_uncert,model_run, experiment_type)
  File "/oscar/data/deeps/private/bfoxkemp/jnickla1/Thorne_15_codefigurestats/Methods/42_Temp_Alone/1_Run_Means/cent20y_method.py", line 23, in run_method
    tot_uncertb = (hadcrutUncert[i-avg_len_l+1])**2
                   ~~~~~~~~~~~~~^^^^^^^^^^^^^^^
  File "/users/jnickla1/.conda/envs/cleanpy/lib/python3.13/site-packages/pandas/core/series.py", line 1121, in __getitem__
    return self._get_value(key)
           ~~~~~~~~~~~~~~~^^^^^
  File "/users/jnickla1/.conda/envs/cleanpy/lib/python3.13/site-packages/pandas/core/series.py", line 1237, in _get_value
    loc = self.index.get_loc(label)
  File "/users/jnickla1/.conda/envs/cleanpy/lib/python3.13/site-packages/pandas/core/indexes/range.py", line 415, in get_loc
    raise KeyError(key) from err
KeyError: 157
All processes completed.
